Workbook

Sheet SO Helper Main
Y1: Temp | Z1: Density
B2: TANK DIP & DENSITY CHART | Y2: 20
B3: Bharat Petroleum Corporation Limited : Calicut Territory | L3: L | M3: =VLOOKUP(C5,M12:O28,2,0) -> 3.99 | Y3: 20.5
L4: D | M4: =VLOOKUP(C5,M12:O28,3,0) -> 1.84 | Y4: 21
B5: Select Tankage | C5: 10KL(1.84D) | L5: R | M5: =M4/2 -> 0.92 | Y5: 21.5
B6: =IF(C5="OTHER","",CONCATENATE(" Tank details : Selected Tank has a Dia of ",$M$4," M and a length of ",$M$3," M . Please select OTHER if it doesn't match with your Tank Spec")) -> Tank details : Selected Tank has a Dia of 1.84 M and a length of 3.99 M . Please select OTHER if it doesn't match with your Tank Spec | Y6: 22
B7: =IF(C5="OTHER","Enter the Length and Diameter of the Tank in Meters : ","") | E7: =IF(C5="OTHER","Length:","") | G7: =IF(C5="OTHER","Diameter:","") | Y7: 22.5
L8: H | M8: L | N8: R | O8: H/R | P8: COSalfa=1-H/R | Q8: Alfa | R8: Sin# | S8: Sin#Cos# | T8: F-H | U8: L*R*R*J*1000 | Y8: 23
B9: ENTER DIP IN CM | C9: 64.8 | D9: CM | U9: qty in Lts | Y9: 23.5
L10: =$C$9/100 -> 0.648 | M10: =M3 -> 3.99 | N10: =M5 -> 0.92 | O10: =L10/N10 -> 0.70434783 | P10: =1-O10 -> 0.29565217 | Q10: =ACOS(P10) -> 1.2706582 | R10: =SIN(Q10) -> 0.95529566 | S10: =P10*R10 -> 0.28243524 | T10: =Q10-S10 -> 0.98822295 | U10: =M10*N10*N10*T10*1000 -> 3337.3633 | Y10: 24
B11: TANK STOCK | C11: =$U$10 -> 3337.3633 | D11: LTRS | Y11: 24.5
M12: Tankage | N12: Length | O12: Diameter | Y12: 25
M13: 10 KL | N13: 3.368 | O13: 2 | Y13: 25.5
M14: 15KL(1.84D) | N14: 5.98 | O14: 1.84 | Y14: 26
B15: Enter natural Density | C15: 730 | M15: 15 KL(NEW) | N15: 4.968 | O15: 2 | Y15: 26.5
B16: Enter the Temperature | C16: 31 | M16: 20 OLD | N16: 6 | O16: 2.1 | Y16: 27
B17: Density at 15 Deg | C17: =ASTM_1980_53B_D15!F4 -> 744.3 | M17: 20 NEW | N17: 6.718 | O17: 2 | Y17: 27.5
M18: 8398L | N18: 2.997 | O18: 1.943 | Y18: 28
M19: 9093L | N19: 3.6576 | O19: 1.8288 | Y19: 28.5
M20: 9KL(1.82D) | N20: 3.6576 | O20: 1.8288 | Y20: 29
M21: 9KL(2.88D) | N21: 3.6576 | O21: 2.88 | Y21: 29.5
M22: 10KL(1.84D) | N22: 3.99 | O22: 1.84 | Y22: 30
M23: 10KL(1.90D) | N23: 3.689 | O23: 1.905 | Y23: 30.5
M24: 10KL(1.93D) | N24: 4.1021 | O24: 1.9304 | Y24: 31
M25: 40KL | N25: 7.62 | O25: 2.819 | Y25: 31.5
M26: 45 KL | N26: 8.25 | O26: 2.738 | Y26: 32
M27: 70KL | N27: 13 | O27: 2.738 | Y27: 32.5
M28: OTHER | N28: =$F$7 -> 0 | O28: =$H$7 -> 0 | Y28: 33
Y29: 33.5
Y30: 34
Y31: 34.5
Y32: 35
Y33: 35.5
Y34: 36
Y35: 36.5
Y36: 37
Y37: 37.5
Y38: 38
Y39: 38.5
Y40: 39
...

Sheet ASTM_1980_53B_D15
A1: EXTRACT OF ASTM TABLE 53B (1980 EDITION)
A2: Enter natural Density | F2: ='SO Helper Main'!C15 -> 730 | G2: (it supports from 670 to 929)
A3: Enter the Temperature | F3: ='SO Helper Main'!C16 -> 31 | G3: (it supports from 0 to 50 in order of 0.5 deg)
A4: Density at 15 Deg | F4: =INDEX(B7:IV107,C5,B5) -> 744.3
B5: =MATCH(F2,B6:IV6,0) -> 56 | C5: =MATCH(F3,A7:A107,0) -> 63 | D5: 3 | E5: 4 | F5: 5 | G5: 6 | H5: 7 | I5: 8 | J5: 9 | K5: 12 | L5: 16 | M5: 17 | N5: 18 | O5: 19 | P5: 20 | Q5: 21 | R5: 22 | S5: 23 | T5: 24 | U5: 25 | V5: 26 | W5: 27 | X5: 28 | Y5: 29 | Z5: 30 | AA5: 31 | AB5: 32 | AC5: 33 | AD5: 34 | AE5: 35 | AF5: 36 | AG5: 37 | AH5: 38 | AI5: 39 | AJ5: 40 | AK5: 41 | AL5: 42 | AM5: 43 | AN5: 44 | AO5: 45 | AP5: 46 | AQ5: 47 | AR5: 48 | AS5: 49 | AT5: 50 | AU5: 51 | AV5: 52 | AW5: 53 | AX5: 54 | AY5: 55 | AZ5: 56 | BA5: 57 | BB5: 58 | BC5: 59 | BD5: 60 | BE5: 61 | BF5: 62 | BG5: 63 | BH5: 64 | BI5: 65 | BJ5: 66 | BK5: 67 | BL5: 68 | BM5: 69 | BN5: 70 | BO5: 71 | BP5: 72 | BQ5: 73 | BR5: 74 | BS5: 75 | BT5: 76 | BU5: 77 | BV5: 78 | BW5: 79 | BX5: 80 | BY5: 81 | BZ5: 82 | CA5: 83 | CB5: 84 | CC5: 85 | CD5: 86 | CE5: 87 | CF5: 88 | CG5: 89 | CH5: 90 | CI5: 91 | CJ5: 92 | CK5: 93 | CL5: 94 | CM5: 95 | CN5: 96 | CO5: 97 | CP5: 98 | CQ5: 99 | CR5: 100 | CS5: 101 | CT5: 102 | CU5: 103 | CV5: 104 | CW5: 105 | CX5: 106 | CY5: 107 | CZ5: 108 | DA5: 109 | DB5: 110 | DM5: 111 | DN5: 112 | DO5: 113 | DP5: 114 | DQ5: 115 | DR5: 116 | DS5: 117 | DT5: 118 | DU5: 119 | DV5: 120 | DW5: 121 | DX5: 122 | DY5: 123 | DZ5: 124 | EA5: 125 | EB5: 126 | EC5: 127 | ED5: 128 | EE5: 129 | EF5: 130 | EG5: 131 | EH5: 132 | EI5: 133 | EJ5: 134 | EK5: 135 | EL5: 136 | EM5: 137 | EN5: 138 | EO5: 139 | EP5: 140 | EQ5: 141 | ER5: 142 | ES5: 143 | ET5: 144 | EU5: 145 | EV5: 146 | EW5: 147 | EX5: 148 | EY5: 149 | EZ5: 150 | FA5: 151 | FB5: 152 | FC5: 153 | FD5: 154 | FE5: 155 | FF5: 156 | FG5: 157 | FH5: 158 | FI5: 159 | FJ5: 160 | FK5: 161 | FL5: 162 | FM5: 163 | FN5: 164 | FO5: 165 | FP5: 166 | FQ5: 167 | FR5: 168 | FS5: 169 | FT5: 170 | FU5: 171 | FV5: 172 | FW5: 173 | FX5: 174 | FY5: 175 | FZ5: 176 | GA5: 177 | GB5: 178 | GC5: 179 | GD5: 180 | GE5: 181 | GF5: 182 | GG5: 183 | GH5: 184 | GI5: 185 | GJ5: 186 | GK5: 187 | GL5: 188 | GM5: 189 | GN5: 190 | GO5: 191 | GP5: 192 | GQ5: 193 | GR5: 194 | GS5: 195 | GT5: 196 | GU5: 197 | GV5: 198 | GW5: 199 | GX5: 200 | GY5: 201 | GZ5: 202 | HA5: 203 | HB5: 204 | HC5: 205 | HD5: 206 | HE5: 207 | HF5: 208 | HG5: 209 | HH5: 210 | HI5: 211 | HJ5: 212 | HK5: 213 | HL5: 214 | HM5: 215 | HN5: 216 | HO5: 217 | HP5: 218 | HQ5: 219 | HR5: 220 | HS5: 221 | HT5: 222 | HU5: 223 | HV5: 224 | HW5: 225 | HX5: 226 | HY5: 227 | HZ5: 228 | IA5: 229 | IB5: 230 | IC5: 231 | ID5: 232 | IE5: 233 | IF5: 234 | IG5: 235 | IH5: 236 | II5: 237 | IJ5: 238 | IK5: 239 | IL5: 240 | IM5: 241 | IN5: 242 | IO5: 243 | IP5: 244 | IQ5: 245 | IR5: 246 | IS5: 247 | IT5: 248 | IU5: 249 | IV5: 250
B6: 670 | C6: 671 | D6: 672 | E6: 673 | F6: 674 | G6: 675 | H6: 676 | I6: 677 | J6: 678 | K6: 681 | L6: 685 | M6: 686 | N6: 687 | O6: 688 | P6: 689 | Q6: 690 | R6: 691 | S6: 692 | T6: 693 | U6: 694 | V6: 695 | W6: 696 | X6: 697 | Y6: 698 | Z6: 699 | AA6: 700 | AB6: 701 | AC6: 702 | AD6: 703 | AE6: 704 | AF6: 705 | AG6: 706 | AH6: 707 | AI6: 708 | AJ6: 709 | AK6: 710 | AL6: 711 | AM6: 712 | AN6: 713 | AO6: 714 | AP6: 715 | AQ6: 716 | AR6: 717 | AS6: 718 | AT6: 719 | AU6: 720 | AV6: 721 | AW6: 722 | AX6: 723 | AY6: 724 | AZ6: 725 | BA6: 726 | BB6: 727 | BC6: 728 | BD6: 729 | BE6: 730 | BF6: 731 | BG6: 732 | BH6: 733 | BI6: 734 | BJ6: 735 | BK6: 736 | BL6: 737 | BM6: 738 | BN6: 739 | BO6: 740 | BP6: 741 | BQ6: 742 | BR6: 743 | BS6: 744 | BT6: 745 | BU6: 746 | BV6: 747 | BW6: 748 | BX6: 749 | BY6: 750 | BZ6: 751 | CA6: 752 | CB6: 753 | CC6: 754 | CD6: 755 | CE6: 756 | CF6: 757 | CG6: 758 | CH6: 759 | CI6: 760 | CJ6: 761 | CK6: 762 | CL6: 763 | CM6: 764 | CN6: 765 | CO6: 766 | CP6: 767 | CQ6: 768 | CR6: 769 | CS6: 770 | CT6: 771 | CU6: 772 | CV6: 773 | CW6: 774 | CX6: 775 | CY6: 776 | CZ6: 777 | DA6: 778 | DB6: 779 | DC6: 780 | DD6: 781 | DE6: 782 | DF6: 783 | DG6: 784 | DH6: 785 | DI6: 786 | DJ6: 787 | DK6: 788 | DL6: 789 | DM6: 790 | DN6: 791 | DO6: 792 | DP6: 793 | DQ6: 794 | DR6: 795 | DS6: 796 | DT6: 797 | DU6: 798 | DV6: 799 | DW6: 800 | DX6: 801 | DY6: 802 | DZ6: 803 | EA6: 804 | EB6: 805 | EC6: 806 | ED6: 807 | EE6: 808 | EF6: 809 | EG6: 810 | EH6: 811 | EI6: 812 | EJ6: 813 | EK6: 814 | EL6: 815 | EM6: 816 | EN6: 817 | EO6: 818 | EP6: 819 | EQ6: 820 | ER6: 821 | ES6: 822 | ET6: 823 | EU6: 824 | EV6: 825 | EW6: 826 | EX6: 827 | EY6: 828 | EZ6: 829 | FA6: 830 | FB6: 831 | FC6: 832 | FD6: 833 | FE6: 834 | FF6: 835 | FG6: 836 | FH6: 837 | FI6: 838 | FJ6: 839 | FK6: 840 | FL6: 841 | FM6: 842 | FN6: 843 | FO6: 844 | FP6: 845 | FQ6: 846 | FR6: 847 | FS6: 848 | FT6: 849 | FU6: 850 | FV6: 851 | FW6: 852 | FX6: 853 | FY6: 854 | FZ6: 855 | GA6: 856 | GB6: 857 | GC6: 858 | GD6: 859 | GE6: 860 | GF6: 861 | GG6: 862 | GH6: 863 | GI6: 864 | GJ6: 865 | GK6: 866 | GL6: 867 | GM6: 868 | GN6: 869 | GO6: 870 | GP6: 871 | GQ6: 872 | GR6: 873 | GS6: 874 | GT6: 875 | GU6: 876 | GV6: 877 | GW6: 878 | GX6: 879 | GY6: 880 | GZ6: 881 | HA6: 882 | HB6: 883 | HC6: 884 | HD6: 885 | HE6: 886 | HF6: 887 | HG6: 888 | HH6: 889 | HI6: 890 | HJ6: 891 | HK6: 892 | HL6: 893 | HM6: 894 | HN6: 895 | HO6: 896 | HP6: 897 | HQ6: 898 | HR6: 899 | HS6: 900 | HT6: 901 | HU6: 902 | HV6: 903 | HW6: 904 | HX6: 905 | HY6: 906 | HZ6: 907 | IA6: 908 | IB6: 909 | IC6: 910 | ID6: 911 | IE6: 912 | IF6: 913 | IG6: 914 | IH6: 915 | II6: 916 | IJ6: 917 | IK6: 918 | IL6: 919 | IM6: 920 | IN6: 921 | IO6: 922 | IP6: 923 | IQ6: 924 | IR6: 925 | IS6: 926 | IT6: 927 | IU6: 928 | IV6: 929
A7: 0 | B7: 655.8 | C7: 656.8 | D7: 657.9 | E7: 658.9 | F7: 659.9 | G7: 660.9 | H7: 661.9 | I7: 662.9 | J7: 663.9 | K7: 667 | L7: 671 | M7: 672 | N7: 673 | O7: 674 | P7: 675 | Q7: 676.1 | R7: 677.1 | S7: 678.1 | T7: 679.1 | U7: 680.1 | V7: 681.1 | W7: 682.1 | X7: 683.1 | Y7: 684.2 | Z7: 685.2 | AA7: 686.2 | AB7: 687.2 | AC7: 688.2 | AD7: 689.2 | AE7: 690.2 | AF7: 691.2 | AG7: 692.2 | AH7: 693.3 | AI7: 694.3 | AJ7: 695.3 | AK7: 696.3 | AL7: 697.3 | AM7: 698.3 | AN7: 699.3 | AO7: 700.3 | AP7: 701.3 | AQ7: 702.3 | AR7: 703.4 | AS7: 704.4 | AT7: 705.4 | AU7: 706.4 | AV7: 707.4 | AW7: 708.4 | AX7: 709.4 | AY7: 710.4 | AZ7: 711.4 | BA7: 712.5 | BB7: 713.5 | BC7: 714.5 | BD7: 715.5 | BE7: 716.5 | BF7: 717.5 | BG7: 718.5 | BH7: 719.5 | BI7: 720.5 | BJ7: 721.5 | BK7: 722.6 | BL7: 723.6 | BM7: 724.6 | BN7: 725.6 | BO7: 726.6 | BP7: 727.6 | BQ7: 728.6 | BR7: 729.6 | BS7: 730.6 | BT7: 731.6 | BU7: 732.7 | BV7: 733.7 | BW7: 734.7 | BX7: 735.7 | BY7: 736.7 | BZ7: 737.7 | CA7: 738.7 | CB7: 739.7 | CC7: 740.7 | CD7: 741.8 | CE7: 742.8 | CF7: 743.8 | CG7: 744.8 | CH7: 745.8 | CI7: 746.8 | CJ7: 747.8 | CK7: 748.8 | CL7: 749.8 | CM7: 750.8 | CN7: 751.8 | CO7: 752.9 | CP7: 753.9 | CQ7: 754.9 | CR7: 755.9 | CS7: 756.9 | CT7: 757.9 | CU7: 758.9 | CV7: 759.9 | CW7: 760.9 | CX7: 761.9 | CY7: 762.9 | CZ7: 763.9 | DA7: 765 | DB7: 766 | DC7: =DB7+1 -> 767 | DD7: =DC7+1 -> 768 | DE7: =DD7+1 -> 769 | DF7: =DE7+1 -> 770 | DG7: =DF7+1 -> 771 | DH7: =DG7+1 -> 772 | DI7: =DH7+1 -> 773 | DJ7: =DI7+1 -> 774 | ... DL7: =DK7+1 -> 776 | DM7: 777.9 | DN7: 779 | DO7: 780.2 | DP7: 781.3 | DQ7: 782.4 | DR7: 783.5 | DS7: 784.7 | DT7: 785.8 | DU7: 786.9 | DV7: 788 | DW7: 789 | DX7: 790 | DY7: 791 | DZ7: 792.1 | EA7: 793.1 | EB7: 794.1 | EC7: 795.1 | ED7: 796.1 | EE7: 797.1 | EF7: 798.2 | EG7: 799.2 | EH7: 800.2 | EI7: 801.2 | EJ7: 802.2 | EK7: 803.2 | EL7: 804.2 | EM7: 805.3 | EN7: 806.3 | EO7: 807.3 | EP7: 808.3 | EQ7: 809.3 | ER7: 810.3 | ES7: 811.3 | ET7: 812.3 | EU7: 813.4 | EV7: 814.4 | EW7: 815.4 | EX7: 816.4 | EY7: 817.4 | EZ7: 818.4 | FA7: 819.4 | FB7: 820.5 | FC7: 821.5 | FD7: 822.5 | FE7: 823.5 | FF7: 824.5 | FG7: 825.5 | FH7: 826.5 | FI7: 827.6 | FJ7: 828.6 | FK7: 829.6 | FL7: 830.6 | FM7: 831.6 | FN7: 832.6 | FO7: 833.6 | FP7: 834.6 | FQ7: 835.7 | FR7: 836.7 | FS7: 837.7 | FT7: 838.7 | FU7: 839.7 | FV7: 840.7 | FW7: 841.7 | FX7: 842.7 | FY7: 843.7 | FZ7: 844.7 | GA7: 845.7 | GB7: 846.7 | GC7: 847.7 | GD7: 848.7 | GE7: 849.7 | GF7: 850.7 | GG7: 851.7 | GH7: 852.7 | GI7: 853.8 | GJ7: 854.8 | GK7: 855.8 | GL7: 856.8 | GM7: 857.8 | GN7: 858.8 | GO7: 859.8 | GP7: 860.8 | GQ7: 861.8 | GR7: 862.8 | GS7: 863.8 | GT7: 864.8 | GU7: 865.8 | GV7: 866.8 | GW7: 867.8 | GX7: 868.8 | GY7: 869.8 | GZ7: 870.8 | HA7: 871.8 | HB7: 872.8 | HC7: 873.8 | HD7: 874.8 | HE7: 875.8 | HF7: 876.8 | HG7: 877.9 | HH7: 878.9 | HI7: 879.9 | HJ7: 880.9 | HK7: 881.9 | HL7: 882.9 | HM7: 883.9 | HN7: 884.9 | HO7: 885.9 | HP7: 886.9 | HQ7: 887.9 | HR7: 888.9 | HS7: 889.9 | HT7: 890.9 | HU7: 891.9 | HV7: 892.9 | HW7: 893.9 | HX7: 894.9 | HY7: 895.9 | HZ7: 896.9 | IA7: 897.9 | IB7: 898.9 | IC7: 899.9 | ID7: 900.9 | IE7: 901.9 | IF7: 902.9 | IG7: 904 | IH7: 905 | II7: 906 | IJ7: 907 | IK7: 908 | IL7: 909 | IM7: 910 | IN7: 911 | IO7: 912 | IP7: 913 | IQ7: 914 | IR7: 915 | IS7: 916 | IT7: 917 | IU7: 918 | IV7: 919
A8: 0.5 | B8: 656.3 | C8: 657.3 | D8: 658.3 | E8: 659.3 | F8: 660.3 | G8: 661.4 | H8: 662.4 | I8: 663.4 | J8: 664.4 | K8: 667.4 | L8: 671.5 | M8: 672.5 | N8: 673.5 | O8: 674.5 | P8: 675.5 | Q8: 676.5 | R8: 677.5 | S8: 678.6 | T8: 679.6 | U8: 680.6 | V8: 681.6 | W8: 682.6 | X8: 683.6 | Y8: 684.6 | Z8: 685.6 | AA8: 686.6 | AB8: 687.6 | AC8: 688.7 | AD8: 689.7 | AE8: 690.7 | AF8: 691.7 | AG8: 692.7 | AH8: 693.7 | AI8: 694.7 | AJ8: 695.7 | AK8: 696.7 | AL8: 697.8 | AM8: 698.8 | AN8: 699.8 | AO8: 700.8 | AP8: 701.8 | AQ8: 702.8 | AR8: 703.8 | AS8: 704.8 | AT8: 705.8 | AU8: 706.9 | AV8: 707.9 | AW8: 708.9 | AX8: 709.9 | AY8: 710.9 | AZ8: 711.9 | BA8: 712.9 | BB8: 713.9 | BC8: 714.9 | BD8: 715.9 | BE8: 716.9 | BF8: 718 | BG8: 719 | BH8: 720 | BI8: 721 | BJ8: 722 | BK8: 723 | BL8: 724 | BM8: 725 | BN8: 726 | BO8: 727 | BP8: 728.1 | BQ8: 729.1 | BR8: 730.1 | BS8: 731.1 | BT8: 732.1 | BU8: 733.1 | BV8: 734.1 | BW8: 735.1 | BX8: 736.1 | BY8: 737.1 | BZ8: 738.2 | CA8: 739.2 | CB8: 740.2 | CC8: 741.2 | CD8: 742.2 | CE8: 743.2 | CF8: 744.2 | CG8: 745.2 | CH8: 746.2 | CI8: 747.2 | CJ8: 748.2 | CK8: 749.3 | CL8: 750.3 | CM8: 751.3 | CN8: 752.3 | CO8: 753.3 | CP8: 754.3 | CQ8: 755.3 | CR8: 756.3 | CS8: 757.3 | CT8: 758.3 | CU8: 759.3 | CV8: 760.3 | CW8: 761.4 | CX8: 762.4 | CY8: 763.4 | CZ8: 764.4 | DA8: 765.4 | DB8: 766.4 | DC8: =DB8+1 -> 767.4 | DD8: =DC8+1 -> 768.4 | DE8: =DD8+1 -> 769.4 | DF8: =DE8+1 -> 770.4 | DG8: =DF8+1 -> 771.4 | DH8: =DG8+1 -> 772.4 | DI8: =DH8+1 -> 773.4 | DJ8: =DI8+1 -> 774.4 | ... DL8: =DK8+1 -> 776.4 | DM8: 778.3 | DN8: 779.5 | DO8: 780.6 | DP8: 781.7 | DQ8: 782.8 | DR8: 784 | DS8: 785.1 | DT8: 786.2 | DU8: 787.3 | DV8: 788.4 | DW8: 789.4 | DX8: 790.4 | DY8: 791.4 | DZ8: 792.4 | EA8: 793.4 | EB8: 794.5 | EC8: 795.5 | ED8: 796.5 | EE8: 797.5 | EF8: 798.5 | EG8: 799.5 | EH8: 800.5 | EI8: 801.6 | EJ8: 802.6 | EK8: 803.6 | EL8: 804.6 | EM8: 805.6 | EN8: 806.6 | EO8: 807.6 | EP8: 808.7 | EQ8: 809.7 | ER8: 810.7 | ES8: 811.7 | ET8: 812.7 | EU8: 813.7 | EV8: 814.7 | EW8: 815.7 | EX8: 816.8 | EY8: 817.8 | EZ8: 818.8 | FA8: 819.8 | FB8: 820.8 | FC8: 821.8 | FD8: 822.8 | FE8: 823.8 | FF8: 824.9 | FG8: 825.9 | FH8: 826.9 | FI8: 827.9 | FJ8: 828.9 | FK8: 829.9 | FL8: 830.9 | FM8: 832 | FN8: 833 | FO8: 834 | FP8: 835 | FQ8: 836 | FR8: 837 | FS8: 838 | FT8: 839 | FU8: 840 | FV8: 841 | FW8: 842 | FX8: 843.1 | FY8: 844.1 | FZ8: 845.1 | GA8: 846.1 | GB8: 847.1 | GC8: 848.1 | GD8: 849.1 | GE8: 850.1 | GF8: 851.1 | GG8: 852.1 | GH8: 853.1 | GI8: 854.1 | GJ8: 855.1 | GK8: 856.1 | GL8: 857.1 | GM8: 858.1 | GN8: 859.1 | GO8: 860.1 | GP8: 861.1 | GQ8: 862.1 | GR8: 863.1 | GS8: 864.1 | GT8: 865.1 | GU8: 866.1 | GV8: 867.2 | GW8: 868.2 | GX8: 869.2 | GY8: 870.2 | GZ8: 871.2 | HA8: 872.2 | HB8: 873.2 | HC8: 874.2 | HD8: 875.2 | HE8: 876.2 | HF8: 877.2 | HG8: 878.2 | HH8: 879.2 | HI8: 880.2 | HJ8: 881.2 | HK8: 882.2 | HL8: 883.2 | HM8: 884.2 | HN8: 885.2 | HO8: 886.2 | HP8: 887.2 | HQ8: 888.2 | HR8: 889.2 | HS8: 890.2 | HT8: 891.2 | HU8: 892.2 | HV8: 893.2 | HW8: 894.3 | HX8: 895.3 | HY8: 896.3 | HZ8: 897.3 | IA8: 898.3 | IB8: 899.3 | IC8: 900.3 | ID8: 901.3 | IE8: 902.3 | IF8: 903.3 | IG8: 904.3 | IH8: 905.3 | II8: 906.3 | IJ8: 907.3 | IK8: 908.3 | IL8: 909.3 | IM8: 910.3 | IN8: 911.3 | IO8: 912.3 | IP8: 913.3 | IQ8: 914.3 | IR8: 915.3 | IS8: 916.3 | IT8: 917.3 | IU8: 918.3 | IV8: 919.3
A9: 1 | B9: 656.8 | C9: 657.8 | D9: 658.8 | E9: 659.8 | F9: 660.8 | G9: 661.8 | H9: 662.8 | I9: 663.9 | J9: 664.9 | K9: 667.9 | L9: 671.9 | M9: 673 | N9: 674 | O9: 675 | P9: 676 | Q9: 677 | R9: 678 | S9: 679 | T9: 680 | U9: 681 | V9: 682 | W9: 683.1 | X9: 684.1 | Y9: 685.1 | Z9: 686.1 | AA9: 687.1 | AB9: 688.1 | AC9: 689.1 | AD9: 690.1 | AE9: 691.1 | AF9: 692.1 | AG9: 693.2 | AH9: 694.2 | AI9: 695.2 | AJ9: 696.2 | AK9: 697.2 | AL9: 698.2 | AM9: 699.2 | AN9: 700.2 | AO9: 701.2 | AP9: 702.3 | AQ9: 703.3 | AR9: 704.3 | AS9: 705.3 | AT9: 706.3 | AU9: 707.3 | AV9: 708.3 | AW9: 709.3 | AX9: 710.3 | AY9: 711.3 | AZ9: 712.4 | BA9: 713.4 | BB9: 714.4 | BC9: 715.4 | BD9: 716.4 | BE9: 717.4 | BF9: 718.4 | BG9: 719.4 | BH9: 720.4 | BI9: 721.4 | BJ9: 722.4 | BK9: 723.5 | BL9: 724.5 | BM9: 725.5 | BN9: 726.5 | BO9: 727.5 | BP9: 728.5 | BQ9: 729.5 | BR9: 730.5 | BS9: 731.5 | BT9: 732.5 | BU9: 733.6 | BV9: 734.6 | BW9: 735.6 | BX9: 736.6 | BY9: 737.6 | BZ9: 738.6 | CA9: 739.6 | CB9: 740.6 | CC9: 741.6 | CD9: 742.6 | CE9: 743.6 | CF9: 744.7 | CG9: 745.7 | CH9: 746.7 | CI9: 747.7 | CJ9: 748.7 | CK9: 749.7 | CL9: 750.7 | CM9: 751.7 | CN9: 752.7 | CO9: 753.7 | CP9: 754.7 | CQ9: 755.7 | CR9: 756.8 | CS9: 757.8 | CT9: 758.8 | CU9: 759.8 | CV9: 760.8 | CW9: 761.8 | CX9: 762.8 | CY9: 763.8 | CZ9: 764.8 | DA9: 765.8 | DB9: 766.8 | DC9: =DB9+1 -> 767.8 | DD9: =DC9+1 -> 768.8 | DE9: =DD9+1 -> 769.8 | DF9: =DE9+1 -> 770.8 | DG9: =DF9+1 -> 771.8 | DH9: =DG9+1 -> 772.8 | DI9: =DH9+1 -> 773.8 | DJ9: =DI9+1 -> 774.8 | ... DL9: =DK9+1 -> 776.8 | DM9: 778.8 | DN9: 779.9 | DO9: 781 | DP9: 782.1 | DQ9: 783.3 | DR9: 784.4 | DS9: 785.5 | DT9: 786.6 | DU9: 787.7 | DV9: 788.7 | DW9: 789.8 | DX9: 790.8 | DY9: 791.8 | DZ9: 792.8 | EA9: 793.8 | EB9: 794.8 | EC9: 795.8 | ED9: 796.9 | EE9: 797.9 | EF9: 798.9 | EG9: 799.9 | EH9: 800.9 | EI9: 801.9 | EJ9: 802.9 | EK9: 803.9 | EL9: 805 | EM9: 806 | EN9: 807 | EO9: 808 | EP9: 809 | EQ9: 810 | ER9: 811 | ES9: 812.1 | ET9: 813.1 | EU9: 814.1 | EV9: 815.1 | EW9: 816.1 | EX9: 817.1 | EY9: 818.1 | EZ9: 819.1 | FA9: 820.2 | FB9: 821.2 | FC9: 822.2 | FD9: 823.2 | FE9: 824.2 | FF9: 825.2 | FG9: 826.2 | FH9: 827.2 | FI9: 828.3 | FJ9: 829.3 | FK9: 830.3 | FL9: 831.3 | FM9: 832.3 | FN9: 833.3 | FO9: 834.3 | FP9: 835.3 | FQ9: 836.4 | FR9: 837.4 | FS9: 838.4 | FT9: 839.4 | FU9: 840.4 | FV9: 841.4 | FW9: 842.4 | FX9: 843.4 | FY9: 844.4 | FZ9: 845.4 | GA9: 846.4 | GB9: 847.4 | GC9: 848.4 | GD9: 849.4 | GE9: 850.4 | GF9: 851.4 | GG9: 852.4 | GH9: 853.4 | GI9: 854.4 | GJ9: 855.4 | GK9: 856.5 | GL9: 857.5 | GM9: 858.5 | GN9: 859.5 | GO9: 860.5 | GP9: 861.5 | GQ9: 862.5 | GR9: 863.5 | GS9: 864.5 | GT9: 865.5 | GU9: 866.5 | GV9: 867.5 | GW9: 868.5 | GX9: 869.5 | GY9: 870.5 | GZ9: 871.5 | HA9: 872.5 | HB9: 873.5 | HC9: 874.5 | HD9: 875.5 | HE9: 876.5 | HF9: 877.5 | HG9: 878.5 | HH9: 879.5 | HI9: 880.5 | HJ9: 881.5 | HK9: 882.5 | HL9: 883.5 | HM9: 884.5 | HN9: 885.5 | HO9: 886.6 | HP9: 887.6 | HQ9: 888.6 | HR9: 889.6 | HS9: 890.6 | HT9: 891.6 | HU9: 892.6 | HV9: 893.6 | HW9: 894.6 | HX9: 895.6 | HY9: 896.6 | HZ9: 897.6 | IA9: 898.6 | IB9: 899.6 | IC9: 900.6 | ID9: 901.6 | IE9: 902.6 | IF9: 903.6 | IG9: 904.6 | IH9: 905.6 | II9: 906.6 | IJ9: 907.6 | IK9: 908.6 | IL9: 909.6 | IM9: 910.6 | IN9: 911.6 | IO9: 912.6 | IP9: 913.7 | IQ9: 914.7 | IR9: 915.7 | IS9: 916.7 | IT9: 917.7 | IU9: 918.7 | IV9: 919.7
A10: 1.5 | B10: 657.3 | C10: 658.3 | D10: 659.3 | E10: 660.3 | F10: 661.3 | G10: 662.3 | H10: 663.3 | I10: 664.3 | J10: 665.3 | K10: 668.4 | L10: 672.4 | M10: 673.4 | N10: 674.4 | O10: 675.4 | P10: 676.4 | Q10: 677.5 | R10: 678.5 | S10: 679.5 | T10: 680.5 | U10: 681.5 | V10: 682.5 | W10: 683.5 | X10: 684.5 | Y10: 685.5 | Z10: 686.5 | AA10: 687.6 | AB10: 688.6 | AC10: 689.6 | AD10: 690.6 | AE10: 691.6 | AF10: 692.6 | AG10: 693.6 | AH10: 694.6 | AI10: 695.6 | AJ10: 696.7 | AK10: 697.7 | AL10: 698.7 | AM10: 699.7 | AN10: 700.7 | AO10: 701.7 | AP10: 702.7 | AQ10: 703.7 | AR10: 704.7 | AS10: 705.7 | AT10: 706.7 | AU10: 707.8 | AV10: 708.8 | AW10: 709.8 | AX10: 710.8 | AY10: 711.8 | AZ10: 712.8 | BA10: 713.8 | BB10: 714.8 | BC10: 715.8 | BD10: 716.8 | BE10: 717.8 | BF10: 718.9 | BG10: 719.9 | BH10: 720.9 | BI10: 721.9 | BJ10: 722.9 | BK10: 723.9 | BL10: 724.9 | BM10: 725.9 | BN10: 726.9 | BO10: 727.9 | BP10: 729 | BQ10: 730 | BR10: 731 | BS10: 732 | BT10: 733 | BU10: 734 | BV10: 735 | BW10: 736 | BX10: 737 | BY10: 738 | BZ10: 739 | CA10: 740.1 | CB10: 741.1 | CC10: 742.1 | CD10: 743.1 | CE10: 744.1 | CF10: 745.1 | CG10: 746.1 | CH10: 747.1 | CI10: 748.1 | CJ10: 749.1 | CK10: 750.1 | CL10: 751.1 | CM10: 752.1 | CN10: 753.2 | CO10: 754.2 | CP10: 755.2 | CQ10: 756.2 | CR10: 757.2 | CS10: 758.2 | CT10: 759.2 | CU10: 760.2 | CV10: 761.2 | CW10: 762.2 | CX10: 763.2 | CY10: 764.3 | CZ10: 765.3 | DA10: 766.3 | DB10: 767.3 | DC10: =DB10+1 -> 768.3 | DD10: =DC10+1 -> 769.3 | DE10: =DD10+1 -> 770.3 | DF10: =DE10+1 -> 771.3 | DG10: =DF10+1 -> 772.3 | DH10: =DG10+1 -> 773.3 | DI10: =DH10+1 -> 774.3 | DJ10: =DI10+1 -> 775.3 | ... DL10: =DK10+1 -> 777.3 | DM10: 779.2 | DN10: 780.3 | DO10: 781.5 | DP10: 782.6 | DQ10: 783.7 | DR10: 784.8 | DS10: 785.9 | DT10: 787 | DU10: 788.1 | DV10: 789.1 | DW10: 790.1 | DX10: 791.1 | DY10: 792.2 | DZ10: 793.2 | EA10: 794.2 | EB10: 795.2 | EC10: 796.2 | ED10: 797.2 | EE10: 798.2 | EF10: 799.2 | EG10: 800.3 | EH10: 801.3 | EI10: 802.3 | EJ10: 803.3 | EK10: 804.3 | EL10: 805.3 | EM10: 806.3 | EN10: 807.3 | EO10: 808.4 | EP10: 809.4 | EQ10: 810.4 | ER10: 811.4 | ES10: 812.4 | ET10: 813.4 | EU10: 814.4 | EV10: 815.4 | EW10: 816.5 | EX10: 817.5 | EY10: 818.5 | EZ10: 819.5 | FA10: 820.5 | FB10: 821.5 | FC10: 822.5 | FD10: 823.5 | FE10: 824.6 | FF10: 825.6 | FG10: 826.6 | FH10: 827.6 | FI10: 828.6 | FJ10: 829.6 | FK10: 830.6 | FL10: 831.6 | FM10: 832.7 | FN10: 833.7 | FO10: 834.7 | FP10: 835.7 | FQ10: 836.7 | FR10: 837.7 | FS10: 838.7 | FT10: 839.7 | FU10: 840.7 | FV10: 841.7 | FW10: 842.7 | FX10: 843.7 | FY10: 844.7 | FZ10: 845.7 | GA10: 846.7 | GB10: 847.8 | GC10: 848.8 | GD10: 849.8 | GE10: 850.8 | GF10: 851.8 | GG10: 852.8 | GH10: 853.8 | GI10: 854.8 | GJ10: 855.8 | GK10: 856.8 | GL10: 857.8 | GM10: 858.8 | GN10: 859.8 | GO10: 860.8 | GP10: 861.8 | GQ10: 862.8 | GR10: 863.8 | GS10: 864.8 | GT10: 865.8 | GU10: 866.8 | GV10: 867.8 | GW10: 868.8 | GX10: 869.8 | GY10: 870.8 | GZ10: 871.8 | HA10: 872.8 | HB10: 873.8 | HC10: 874.9 | HD10: 875.9 | HE10: 876.9 | HF10: 877.9 | HG10: 878.9 | HH10: 879.9 | HI10: 880.9 | HJ10: 881.9 | HK10: 882.9 | HL10: 883.9 | HM10: 884.9 | HN10: 885.9 | HO10: 886.9 | HP10: 887.9 | HQ10: 888.9 | HR10: 889.9 | HS10: 890.9 | HT10: 891.9 | HU10: 892.9 | HV10: 893.9 | HW10: 894.9 | HX10: 895.9 | HY10: 896.9 | HZ10: 897.9 | IA10: 898.9 | IB10: 899.9 | IC10: 900.9 | ID10: 901.9 | IE10: 903 | IF10: 904 | IG10: 905 | IH10: 906 | II10: 907 | IJ10: 908 | IK10: 909 | IL10: 910 | IM10: 911 | IN10: 912 | IO10: 913 | IP10: 914 | IQ10: 915 | IR10: 916 | IS10: 917 | IT10: 918 | IU10: 919 | IV10: 920
A11: 2 | B11: 657.7 | C11: 658.7 | D11: 659.7 | E11: 660.8 | F11: 661.8 | G11: 662.8 | H11: 663.8 | I11: 664.8 | J11: 665.8 | K11: 668.8 | L11: 672.9 | M11: 673.9 | N11: 674.9 | O11: 675.9 | P11: 676.9 | Q11: 677.9 | R11: 678.9 | S11: 679.9 | T11: 681 | U11: 682 | V11: 683 | W11: 684 | X11: 685 | Y11: 686 | Z11: 687 | AA11: 688 | AB11: 689 | AC11: 690 | AD11: 691.1 | AE11: 692.1 | AF11: 693.1 | AG11: 694.1 | AH11: 695.1 | AI11: 696.1 | AJ11: 697.1 | AK11: 698.1 | AL11: 699.1 | AM11: 700.1 | AN11: 701.1 | AO11: 702.2 | AP11: 703.2 | AQ11: 704.2 | AR11: 705.2 | AS11: 706.2 | AT11: 707.2 | AU11: 708.2 | AV11: 709.2 | AW11: 710.2 | AX11: 711.2 | AY11: 712.2 | AZ11: 713.3 | BA11: 714.3 | BB11: 715.3 | BC11: 716.3 | BD11: 717.3 | BE11: 718.3 | BF11: 719.3 | BG11: 720.3 | BH11: 721.3 | BI11: 722.3 | BJ11: 723.4 | BK11: 724.4 | BL11: 725.4 | BM11: 726.4 | BN11: 727.4 | BO11: 728.4 | BP11: 729.4 | BQ11: 730.4 | BR11: 731.4 | BS11: 732.4 | BT11: 733.4 | BU11: 734.4 | BV11: 735.5 | BW11: 736.5 | BX11: 737.5 | BY11: 738.5 | BZ11: 739.5 | CA11: 740.5 | CB11: 741.5 | CC11: 742.5 | CD11: 743.5 | CE11: 744.5 | CF11: 745.5 | CG11: 746.5 | CH11: 747.5 | CI11: 748.6 | CJ11: 749.6 | CK11: 750.6 | CL11: 751.6 | CM11: 752.6 | CN11: 753.6 | CO11: 754.6 | CP11: 755.6 | CQ11: 756.6 | CR11: 757.6 | CS11: 758.6 | CT11: 759.7 | CU11: 760.7 | CV11: 761.7 | CW11: 762.7 | CX11: 763.7 | CY11: 764.7 | CZ11: 765.7 | DA11: 766.7 | DB11: 767.7 | DC11: =DB11+1 -> 768.7 | DD11: =DC11+1 -> 769.7 | DE11: =DD11+1 -> 770.7 | DF11: =DE11+1 -> 771.7 | DG11: =DF11+1 -> 772.7 | DH11: =DG11+1 -> 773.7 | DI11: =DH11+1 -> 774.7 | DJ11: =DI11+1 -> 775.7 | ... DL11: =DK11+1 -> 777.7 | DM11: 779.7 | DN11: 780.8 | DO11: 781.9 | DP11: 783 | DQ11: 784.1 | DR11: 785.2 | DS11: 786.3 | DT11: 787.5 | DU11: 788.5 | DV11: 789.5 | DW11: 790.5 | DX11: 791.5 | DY11: 792.5 | DZ11: 793.5 | EA11: 794.5 | EB11: 795.6 | EC11: 796.6 | ED11: 797.6 | EE11: 798.6 | EF11: 799.6 | EG11: 800.6 | EH11: 801.6 | EI11: 802.6 | EJ11: 803.7 | EK11: 804.7 | EL11: 805.7 | EM11: 806.7 | EN11: 807.7 | EO11: 808.7 | EP11: 809.7 | EQ11: 810.7 | ER11: 811.8 | ES11: 812.8 | ET11: 813.8 | EU11: 814.8 | EV11: 815.8 | EW11: 816.8 | EX11: 817.8 | EY11: 818.8 | EZ11: 819.9 | FA11: 820.9 | FB11: 821.9 | FC11: 822.9 | FD11: 823.9 | FE11: 824.9 | FF11: 825.9 | FG11: 826.9 | FH11: 827.9 | FI11: 829 | FJ11: 830 | FK11: 831 | FL11: 832 | FM11: 833 | FN11: 834 | FO11: 835 | FP11: 836 | FQ11: 837 | FR11: 838.1 | FS11: 839.1 | FT11: 840.1 | FU11: 841.1 | FV11: 842.1 | FW11: 843.1 | FX11: 844.1 | FY11: 845.1 | FZ11: 846.1 | GA11: 847.1 | GB11: 848.1 | GC11: 849.1 | GD11: 850.1 | GE11: 851.1 | GF11: 852.1 | GG11: 853.1 | GH11: 854.1 | GI11: 855.1 | GJ11: 856.1 | GK11: 857.1 | GL11: 858.1 | GM11: 859.1 | GN11: 860.1 | GO11: 861.1 | GP11: 862.1 | GQ11: 863.2 | GR11: 864.2 | GS11: 865.2 | GT11: 866.2 | GU11: 867.2 | GV11: 868.2 | GW11: 869.2 | GX11: 870.2 | GY11: 871.2 | GZ11: 872.2 | HA11: 873.2 | HB11: 874.2 | HC11: 875.2 | HD11: 876.2 | HE11: 877.2 | HF11: 878.2 | HG11: 879.2 | HH11: 880.2 | HI11: 881.2 | HJ11: 882.2 | HK11: 883.2 | HL11: 884.2 | HM11: 885.2 | HN11: 886.2 | HO11: 887.2 | HP11: 888.2 | HQ11: 889.2 | HR11: 890.2 | HS11: 891.3 | HT11: 892.3 | HU11: 893.3 | HV11: 894.3 | HW11: 895.3 | HX11: 896.3 | HY11: 897.3 | HZ11: 898.3 | IA11: 899.3 | IB11: 900.3 | IC11: 901.3 | ID11: 902.3 | IE11: 903.3 | IF11: 904.3 | IG11: 905.3 | IH11: 906.3 | II11: 907.3 | IJ11: 908.3 | IK11: 909.3 | IL11: 910.3 | IM11: 911.3 | IN11: 912.3 | IO11: 913.3 | IP11: 914.3 | IQ11: 915.3 | IR11: 916.3 | IS11: 917.3 | IT11: 918.3 | IU11: 919.3 | IV11: 920.3
A12: 2.5 | B12: 658.2 | C12: 659.2 | D12: 660.2 | E12: 661.2 | F12: 662.2 | G12: 663.2 | H12: 664.3 | I12: 665.3 | J12: 666.3 | K12: 669.3 | L12: 673.3 | M12: 674.4 | N12: 675.4 | O12: 676.4 | P12: 677.4 | Q12: 678.4 | R12: 679.4 | S12: 680.4 | T12: 681.4 | U12: 682.4 | V12: 683.4 | W12: 684.5 | X12: 685.5 | Y12: 686.5 | Z12: 687.5 | AA12: 688.5 | AB12: 689.5 | AC12: 690.5 | AD12: 691.5 | AE12: 692.5 | AF12: 693.5 | AG12: 694.5 | AH12: 695.6 | AI12: 696.6 | AJ12: 697.6 | AK12: 698.6 | AL12: 699.6 | AM12: 700.6 | AN12: 701.6 | AO12: 702.6 | AP12: 703.6 | AQ12: 704.6 | AR12: 705.6 | AS12: 706.6 | AT12: 707.7 | AU12: 708.7 | AV12: 709.7 | AW12: 710.7 | AX12: 711.7 | AY12: 712.7 | AZ12: 713.7 | BA12: 714.7 | BB12: 715.7 | BC12: 716.7 | BD12: 717.7 | BE12: 718.8 | BF12: 719.8 | BG12: 720.8 | BH12: 721.8 | BI12: 722.8 | BJ12: 723.8 | BK12: 724.8 | BL12: 725.8 | BM12: 726.8 | BN12: 727.8 | BO12: 728.8 | BP12: 729.8 | BQ12: 730.9 | BR12: 731.9 | BS12: 732.9 | BT12: 733.9 | BU12: 734.9 | BV12: 735.9 | BW12: 736.9 | BX12: 737.9 | BY12: 738.9 | BZ12: 739.9 | CA12: 740.9 | CB12: 741.9 | CC12: 742.9 | CD12: 744 | CE12: 745 | CF12: 746 | CG12: 747 | CH12: 748 | CI12: 749 | CJ12: 750 | CK12: 751 | CL12: 752 | CM12: 753 | CN12: 754 | CO12: 755.1 | CP12: 756.1 | CQ12: 757.1 | CR12: 758.1 | CS12: 759.1 | CT12: 760.1 | CU12: 761.1 | CV12: 762.1 | CW12: 763.1 | CX12: 764.1 | CY12: 765.1 | CZ12: 766.1 | DA12: 767.1 | DB12: 768.1 | DC12: =DB12+1 -> 769.1 | DD12: =DC12+1 -> 770.1 | DE12: =DD12+1 -> 771.1 | DF12: =DE12+1 -> 772.1 | DG12: =DF12+1 -> 773.1 | DH12: =DG12+1 -> 774.1 | DI12: =DH12+1 -> 775.1 | DJ12: =DI12+1 -> 776.1 | ... DL12: =DK12+1 -> 778.1 | DM12: 780.1 | DN12: 781.2 | DO12: 782.3 | DP12: 783.4 | DQ12: 784.5 | DR12: 785.6 | DS12: 786.8 | DT12: 787.8 | DU12: 788.8 | DV12: 789.9 | DW12: 790.9 | DX12: 791.9 | DY12: 792.9 | DZ12: 793.9 | EA12: 794.9 | EB12: 795.9 | EC12: 796.9 | ED12: 797.9 | EE12: 799 | EF12: 800 | EG12: 801 | EH12: 802 | EI12: 803 | EJ12: 804 | EK12: 805 | EL12: 806 | EM12: 807.1 | EN12: 808.1 | EO12: 809.1 | EP12: 810.1 | EQ12: 811.1 | ER12: 812.1 | ES12: 813.1 | ET12: 814.1 | EU12: 815.1 | EV12: 816.2 | EW12: 817.2 | EX12: 818.2 | EY12: 819.2 | EZ12: 820.2 | FA12: 821.2 | FB12: 822.2 | FC12: 823.2 | FD12: 824.3 | FE12: 825.3 | FF12: 826.3 | FG12: 827.3 | FH12: 828.3 | FI12: 829.3 | FJ12: 830.3 | FK12: 831.3 | FL12: 832.3 | FM12: 833.4 | FN12: 834.4 | FO12: 835.4 | FP12: 836.4 | FQ12: 837.4 | FR12: 838.4 | FS12: 839.4 | FT12: 840.4 | FU12: 841.4 | FV12: 842.4 | FW12: 843.4 | FX12: 844.4 | FY12: 845.4 | FZ12: 846.4 | GA12: 847.4 | GB12: 848.4 | GC12: 849.4 | GD12: 850.4 | GE12: 851.4 | GF12: 852.4 | GG12: 853.5 | GH12: 854.5 | GI12: 855.5 | GJ12: 856.5 | GK12: 857.5 | GL12: 858.5 | GM12: 859.5 | GN12: 860.5 | GO12: 861.5 | GP12: 862.5 | GQ12: 863.5 | GR12: 864.5 | GS12: 865.5 | GT12: 866.5 | GU12: 867.5 | GV12: 868.5 | GW12: 869.5 | GX12: 870.5 | GY12: 871.5 | GZ12: 872.5 | HA12: 873.5 | HB12: 874.5 | HC12: 875.5 | HD12: 876.5 | HE12: 877.5 | HF12: 878.5 | HG12: 879.5 | HH12: 880.5 | HI12: 881.5 | HJ12: 882.5 | HK12: 883.6 | HL12: 884.6 | HM12: 885.6 | HN12: 886.6 | HO12: 887.6 | HP12: 888.6 | HQ12: 889.6 | HR12: 890.6 | HS12: 891.6 | HT12: 892.6 | HU12: 893.6 | HV12: 894.6 | HW12: 895.6 | HX12: 896.6 | HY12: 897.6 | HZ12: 898.6 | IA12: 899.6 | IB12: 900.6 | IC12: 901.6 | ID12: 902.6 | IE12: 903.6 | IF12: 904.6 | IG12: 905.6 | IH12: 906.6 | II12: 907.6 | IJ12: 908.6 | IK12: 909.6 | IL12: 910.6 | IM12: 911.6 | IN12: 912.6 | IO12: 913.6 | IP12: 914.7 | IQ12: 915.7 | IR12: 916.7 | IS12: 917.7 | IT12: 918.7 | IU12: 919.7 | IV12: 920.7
A13: 3 | B13: 658.7 | C13: 659.7 | D13: 660.7 | E13: 661.7 | F13: 662.7 | G13: 663.7 | H13: 664.7 | I13: 665.7 | J13: 666.8 | K13: 669.8 | L13: 673.8 | M13: 674.8 | N13: 675.8 | O13: 676.8 | P13: 677.9 | Q13: 678.9 | R13: 679.9 | S13: 680.9 | T13: 681.9 | U13: 682.9 | V13: 683.9 | W13: 684.9 | X13: 685.9 | Y13: 686.9 | Z13: 687.9 | AA13: 688.9 | AB13: 690 | AC13: 691 | AD13: 692 | AE13: 693 | AF13: 694 | AG13: 695 | AH13: 696 | AI13: 697 | AJ13: 698 | AK13: 699 | AL13: 700 | AM13: 701.1 | AN13: 702.1 | AO13: 703.1 | AP13: 704.1 | AQ13: 705.1 | AR13: 706.1 | AS13: 707.1 | AT13: 708.1 | AU13: 709.1 | AV13: 710.1 | AW13: 711.1 | AX13: 712.2 | AY13: 713.2 | AZ13: 714.2 | BA13: 715.2 | BB13: 716.2 | BC13: 717.2 | BD13: 718.2 | BE13: 719.2 | BF13: 720.2 | BG13: 721.2 | BH13: 722.2 | BI13: 723.2 | BJ13: 724.2 | BK13: 725.3 | BL13: 726.3 | BM13: 727.3 | BN13: 728.3 | BO13: 729.3 | BP13: 730.3 | BQ13: 731.3 | BR13: 732.3 | BS13: 733.3 | BT13: 734.3 | BU13: 735.3 | BV13: 736.3 | BW13: 737.3 | BX13: 738.4 | BY13: 739.4 | BZ13: 740.4 | CA13: 741.4 | CB13: 742.4 | CC13: 743.4 | CD13: 744.4 | CE13: 745.4 | CF13: 746.4 | CG13: 747.4 | CH13: 748.4 | CI13: 749.4 | CJ13: 750.5 | CK13: 751.5 | CL13: 752.5 | CM13: 753.5 | CN13: 754.5 | CO13: 755.5 | CP13: 756.5 | CQ13: 757.5 | CR13: 758.5 | CS13: 759.5 | CT13: 760.5 | CU13: 761.5 | CV13: 762.5 | CW13: 763.5 | CX13: 764.6 | CY13: 765.6 | CZ13: 766.6 | DA13: 767.6 | DB13: 768.6 | DC13: =DB13+1 -> 769.6 | DD13: =DC13+1 -> 770.6 | DE13: =DD13+1 -> 771.6 | DF13: =DE13+1 -> 772.6 | DG13: =DF13+1 -> 773.6 | DH13: =DG13+1 -> 774.6 | DI13: =DH13+1 -> 775.6 | DJ13: =DI13+1 -> 776.6 | ... DL13: =DK13+1 -> 778.6 | DM13: 780.6 | DN13: 781.7 | DO13: 782.8 | DP13: 783.9 | DQ13: 785 | DR13: 786.1 | DS13: 787.2 | DT13: 788.2 | DU13: 789.2 | DV13: 790.2 | DW13: 791.2 | DX13: 792.2 | DY13: 793.3 | DZ13: 794.3 | EA13: 795.3 | EB13: 796.3 | EC13: 797.3 | ED13: 798.3 | EE13: 799.3 | EF13: 800.3 | EG13: 801.3 | EH13: 802.4 | EI13: 803.4 | EJ13: 804.4 | EK13: 805.4 | EL13: 806.4 | EM13: 807.4 | EN13: 808.4 | EO13: 809.4 | EP13: 810.4 | EQ13: 811.5 | ER13: 812.5 | ES13: 813.5 | ET13: 814.5 | EU13: 815.5 | EV13: 816.5 | EW13: 817.5 | EX13: 818.5 | EY13: 819.6 | EZ13: 820.6 | FA13: 821.6 | FB13: 822.6 | FC13: 823.6 | FD13: 824.6 | FE13: 825.6 | FF13: 826.6 | FG13: 827.6 | FH13: 828.6 | FI13: 829.7 | FJ13: 830.7 | FK13: 831.7 | FL13: 832.7 | FM13: 833.7 | FN13: 834.7 | FO13: 835.7 | FP13: 836.7 | FQ13: 837.7 | FR13: 838.7 | FS13: 839.8 | FT13: 840.8 | FU13: 841.8 | FV13: 842.8 | FW13: 843.8 | FX13: 844.8 | FY13: 845.8 | FZ13: 846.8 | GA13: 847.8 | GB13: 848.8 | GC13: 849.8 | GD13: 850.8 | GE13: 851.8 | GF13: 852.8 | GG13: 853.8 | GH13: 854.8 | GI13: 855.8 | GJ13: 856.8 | GK13: 857.8 | GL13: 858.8 | GM13: 859.8 | GN13: 860.8 | GO13: 861.8 | GP13: 862.8 | GQ13: 863.8 | GR13: 864.8 | GS13: 865.8 | GT13: 866.8 | GU13: 867.8 | GV13: 868.8 | GW13: 869.9 | GX13: 870.9 | GY13: 871.9 | GZ13: 872.9 | HA13: 873.9 | HB13: 874.9 | HC13: 875.9 | HD13: 876.9 | HE13: 877.9 | HF13: 878.9 | HG13: 879.9 | HH13: 880.9 | HI13: 881.9 | HJ13: 882.9 | HK13: 883.9 | HL13: 884.9 | HM13: 885.9 | HN13: 886.9 | HO13: 887.9 | HP13: 888.9 | HQ13: 889.9 | HR13: 890.9 | HS13: 891.9 | HT13: 892.9 | HU13: 893.9 | HV13: 894.9 | HW13: 895.9 | HX13: 896.9 | HY13: 897.9 | HZ13: 898.9 | IA13: 899.9 | IB13: 900.9 | IC13: 902 | ID13: 903 | IE13: 904 | IF13: 905 | IG13: 906 | IH13: 907 | II13: 908 | IJ13: 909 | IK13: 910 | IL13: 911 | IM13: 912 | IN13: 913 | IO13: 914 | IP13: 915 | IQ13: 916 | IR13: 917 | IS13: 918 | IT13: 919 | IU13: 920 | IV13: 921
A14: 3.5 | B14: 659.1 | C14: 660.2 | D14: 661.2 | E14: 662.2 | F14: 663.2 | G14: 664.2 | H14: 665.2 | I14: 666.2 | J14: 667.2 | K14: 670.2 | L14: 674.3 | M14: 675.3 | N14: 676.3 | O14: 677.3 | P14: 678.3 | Q14: 679.3 | R14: 680.3 | S14: 681.3 | T14: 682.3 | U14: 683.4 | V14: 684.4 | W14: 685.4 | X14: 686.4 | Y14: 687.4 | Z14: 688.4 | AA14: 689.4 | AB14: 690.4 | AC14: 691.4 | AD14: 692.4 | AE14: 693.4 | AF14: 694.4 | AG14: 695.5 | AH14: 696.5 | AI14: 697.5 | AJ14: 698.5 | AK14: 699.5 | AL14: 700.5 | AM14: 701.5 | AN14: 702.5 | AO14: 703.5 | AP14: 704.5 | AQ14: 705.5 | AR14: 706.6 | AS14: 707.6 | AT14: 708.6 | AU14: 709.6 | AV14: 710.6 | AW14: 711.6 | AX14: 712.6 | AY14: 713.6 | AZ14: 714.6 | BA14: 715.6 | BB14: 716.6 | BC14: 717.6 | BD14: 718.6 | BE14: 719.7 | BF14: 720.7 | BG14: 721.7 | BH14: 722.7 | BI14: 723.7 | BJ14: 724.7 | BK14: 725.7 | BL14: 726.7 | BM14: 727.7 | BN14: 728.7 | BO14: 729.7 | BP14: 730.7 | BQ14: 731.7 | BR14: 732.8 | BS14: 733.8 | BT14: 734.8 | BU14: 735.8 | BV14: 736.8 | BW14: 737.8 | BX14: 738.8 | BY14: 739.8 | BZ14: 740.8 | CA14: 741.8 | CB14: 742.8 | CC14: 743.8 | CD14: 744.9 | CE14: 745.9 | CF14: 746.9 | CG14: 747.9 | CH14: 748.9 | CI14: 749.9 | CJ14: 750.9 | CK14: 751.9 | CL14: 752.9 | CM14: 753.9 | CN14: 754.9 | CO14: 755.9 | CP14: 756.9 | CQ14: 757.9 | CR14: 758.9 | CS14: 760 | CT14: 761 | CU14: 762 | CV14: 763 | CW14: 764 | CX14: 765 | CY14: 766 | CZ14: 767 | DA14: 768 | DB14: 769 | DC14: =DB14+1 -> 770 | DD14: =DC14+1 -> 771 | DE14: =DD14+1 -> 772 | DF14: =DE14+1 -> 773 | DG14: =DF14+1 -> 774 | DH14: =DG14+1 -> 775 | DI14: =DH14+1 -> 776 | DJ14: =DI14+1 -> 777 | ... DL14: =DK14+1 -> 779 | DM14: 781 | DN14: 782.1 | DO14: 783.2 | DP14: 784.3 | DQ14: 785.4 | DR14: 786.5 | DS14: 787.6 | DT14: 788.6 | DU14: 789.6 | DV14: 790.6 | DW14: 791.6 | DX14: 792.6 | DY14: 793.6 | DZ14: 794.6 | EA14: 795.6 | EB14: 796.7 | EC14: 797.7 | ED14: 798.7 | EE14: 799.7 | EF14: 800.7 | EG14: 801.7 | EH14: 802.7 | EI14: 803.7 | EJ14: 804.7 | EK14: 805.8 | EL14: 806.8 | EM14: 807.8 | EN14: 808.8 | EO14: 809.8 | EP14: 810.8 | EQ14: 811.8 | ER14: 812.8 | ES14: 813.8 | ET14: 814.9 | EU14: 815.9 | EV14: 816.9 | EW14: 817.9 | EX14: 818.9 | EY14: 819.9 | EZ14: 820.9 | FA14: 821.9 | FB14: 822.9 | FC14: 823.9 | FD14: 825 | FE14: 826 | FF14: 827 | FG14: 828 | FH14: 829 | FI14: 830 | FJ14: 831 | FK14: 832 | FL14: 833 | FM14: 834 | FN14: 835.1 | FO14: 836.1 | FP14: 837.1 | FQ14: 838.1 | FR14: 839.1 | FS14: 840.1 | FT14: 841.1 | FU14: 842.1 | FV14: 843.1 | FW14: 844.1 | FX14: 845.1 | FY14: 846.1 | FZ14: 847.1 | GA14: 848.1 | GB14: 849.1 | GC14: 850.1 | GD14: 851.1 | GE14: 852.1 | GF14: 853.1 | GG14: 854.1 | GH14: 855.1 | GI14: 856.2 | GJ14: 857.2 | GK14: 858.2 | GL14: 859.2 | GM14: 860.2 | GN14: 861.2 | GO14: 862.2 | GP14: 863.2 | GQ14: 864.2 | GR14: 865.2 | GS14: 866.2 | GT14: 867.2 | GU14: 868.2 | GV14: 869.2 | GW14: 870.2 | GX14: 871.2 | GY14: 872.2 | GZ14: 873.2 | HA14: 874.2 | HB14: 875.2 | HC14: 876.2 | HD14: 877.2 | HE14: 878.2 | HF14: 879.2 | HG14: 880.2 | HH14: 881.2 | HI14: 882.2 | HJ14: 883.2 | HK14: 884.2 | HL14: 885.2 | HM14: 886.2 | HN14: 887.2 | HO14: 888.2 | HP14: 889.2 | HQ14: 890.3 | HR14: 891.3 | HS14: 892.3 | HT14: 893.3 | HU14: 894.3 | HV14: 895.3 | HW14: 896.3 | HX14: 897.3 | HY14: 898.3 | HZ14: 899.3 | IA14: 900.3 | IB14: 901.3 | IC14: 902.3 | ID14: 903.3 | IE14: 904.3 | IF14: 905.3 | IG14: 906.3 | IH14: 907.3 | II14: 908.3 | IJ14: 909.3 | IK14: 910.3 | IL14: 911.3 | IM14: 912.3 | IN14: 913.3 | IO14: 914.3 | IP14: 915.3 | IQ14: 916.3 | IR14: 917.3 | IS14: 918.3 | IT14: 919.3 | IU14: 920.3 | IV14: 921.3
A15: 4 | B15: 659.6 | C15: 660.6 | D15: 661.6 | E15: 662.6 | F15: 663.7 | G15: 664.7 | H15: 665.7 | I15: 666.7 | J15: 667.7 | K15: 670.7 | L15: 674.7 | M15: 675.8 | N15: 676.8 | O15: 677.8 | P15: 678.8 | Q15: 679.8 | R15: 680.8 | S15: 681.8 | T15: 682.8 | U15: 683.8 | V15: 684.8 | W15: 685.8 | X15: 686.8 | Y15: 687.9 | Z15: 688.9 | AA15: 689.9 | AB15: 690.9 | AC15: 691.9 | AD15: 692.9 | AE15: 693.9 | AF15: 694.9 | AG15: 695.9 | AH15: 696.9 | AI15: 697.9 | AJ15: 698.9 | AK15: 700 | AL15: 701 | AM15: 702 | AN15: 703 | AO15: 704 | AP15: 705 | AQ15: 706 | AR15: 707 | AS15: 708 | AT15: 709 | AU15: 710 | AV15: 711 | AW15: 712 | AX15: 713.1 | AY15: 714.1 | AZ15: 715.1 | BA15: 716.1 | BB15: 717.1 | BC15: 718.1 | BD15: 719.1 | BE15: 720.1 | BF15: 721.1 | BG15: 722.1 | BH15: 723.1 | BI15: 724.1 | BJ15: 725.1 | BK15: 726.1 | BL15: 727.2 | BM15: 728.2 | BN15: 729.2 | BO15: 730.2 | BP15: 731.2 | BQ15: 732.2 | BR15: 733.2 | BS15: 734.2 | BT15: 735.2 | BU15: 736.2 | BV15: 737.2 | BW15: 738.2 | BX15: 739.3 | BY15: 740.3 | BZ15: 741.3 | CA15: 742.3 | CB15: 743.3 | CC15: 744.3 | CD15: 745.3 | CE15: 746.3 | CF15: 747.3 | CG15: 748.3 | CH15: 749.3 | CI15: 750.3 | CJ15: 751.3 | CK15: 752.3 | CL15: 753.3 | CM15: 754.4 | CN15: 755.4 | CO15: 756.4 | CP15: 757.4 | CQ15: 758.4 | CR15: 759.4 | CS15: 760.4 | CT15: 761.4 | CU15: 762.4 | CV15: 763.4 | CW15: 764.4 | CX15: 765.4 | CY15: 766.4 | CZ15: 767.4 | DA15: 768.5 | DB15: 769.5 | DC15: =DB15+1 -> 770.5 | DD15: =DC15+1 -> 771.5 | DE15: =DD15+1 -> 772.5 | DF15: =DE15+1 -> 773.5 | DG15: =DF15+1 -> 774.5 | DH15: =DG15+1 -> 775.5 | DI15: =DH15+1 -> 776.5 | DJ15: =DI15+1 -> 777.5 | ... DL15: =DK15+1 -> 779.5 | DM15: 781.4 | DN15: 782.5 | DO15: 783.6 | DP15: 784.7 | DQ15: 785.8 | DR15: 786.9 | DS15: 787.9 | DT15: 788.9 | DU15: 789.9 | DV15: 791 | DW15: 792 | DX15: 793 | DY15: 794 | DZ15: 795 | EA15: 796 | EB15: 797 | EC15: 798 | ED15: 799 | EE15: 800.1 | EF15: 801.1 | EG15: 802.1 | EH15: 803.1 | EI15: 804.1 | EJ15: 805.1 | EK15: 806.1 | EL15: 807.1 | EM15: 808.1 | EN15: 809.1 | EO15: 810.2 | EP15: 811.2 | EQ15: 812.2 | ER15: 813.2 | ES15: 814.2 | ET15: 815.2 | EU15: 816.2 | EV15: 817.2 | EW15: 818.2 | EX15: 819.3 | EY15: 820.3 | EZ15: 821.3 | FA15: 822.3 | FB15: 823.3 | FC15: 824.3 | FD15: 825.3 | FE15: 826.3 | FF15: 827.3 | FG15: 828.3 | FH15: 829.3 | FI15: 830.4 | FJ15: 831.4 | FK15: 832.4 | FL15: 833.4 | FM15: 834.4 | FN15: 835.4 | FO15: 836.4 | FP15: 837.4 | FQ15: 838.4 | FR15: 839.4 | FS15: 840.4 | FT15: 841.4 | FU15: 842.4 | FV15: 843.4 | FW15: 844.4 | FX15: 845.5 | FY15: 846.5 | FZ15: 847.5 | GA15: 848.5 | GB15: 849.5 | GC15: 850.5 | GD15: 851.5 | GE15: 852.5 | GF15: 853.5 | GG15: 854.5 | GH15: 855.5 | GI15: 856.5 | GJ15: 857.5 | GK15: 858.5 | GL15: 859.5 | GM15: 860.5 | GN15: 861.5 | GO15: 862.5 | GP15: 863.5 | GQ15: 864.5 | GR15: 865.5 | GS15: 866.5 | GT15: 867.5 | GU15: 868.5 | GV15: 869.5 | GW15: 870.5 | GX15: 871.5 | GY15: 872.5 | GZ15: 873.5 | HA15: 874.5 | HB15: 875.5 | HC15: 876.5 | HD15: 877.5 | HE15: 878.6 | HF15: 879.6 | HG15: 880.6 | HH15: 881.6 | HI15: 882.6 | HJ15: 883.6 | HK15: 884.6 | HL15: 885.6 | HM15: 886.6 | HN15: 887.6 | HO15: 888.6 | HP15: 889.6 | HQ15: 890.6 | HR15: 891.6 | HS15: 892.6 | HT15: 893.6 | HU15: 894.6 | HV15: 895.6 | HW15: 896.6 | HX15: 897.6 | HY15: 898.6 | HZ15: 899.6 | IA15: 900.6 | IB15: 901.6 | IC15: 902.6 | ID15: 903.6 | IE15: 904.6 | IF15: 905.6 | IG15: 906.6 | IH15: 907.6 | II15: 908.6 | IJ15: 909.6 | IK15: 910.6 | IL15: 911.6 | IM15: 912.6 | IN15: 913.7 | IO15: 914.7 | IP15: 915.7 | IQ15: 916.7 | IR15: 917.7 | IS15: 918.7 | IT15: 919.7 | IU15: 920.7 | IV15: 921.7
A16: 4.5 | B16: 660.1 | C16: 661.1 | D16: 662.1 | E16: 663.1 | F16: 664.1 | G16: 665.1 | H16: 666.1 | I16: 667.1 | J16: 668.2 | K16: 671.2 | L16: 675.2 | M16: 676.2 | N16: 677.2 | O16: 678.2 | P16: 679.2 | Q16: 680.3 | R16: 681.3 | S16: 682.3 | T16: 683.3 | U16: 684.3 | V16: 685.3 | W16: 686.3 | X16: 687.3 | Y16: 688.3 | Z16: 689.3 | AA16: 690.3 | AB16: 691.3 | AC16: 692.4 | AD16: 693.4 | AE16: 694.4 | AF16: 695.4 | AG16: 696.4 | AH16: 697.4 | AI16: 698.4 | AJ16: 699.4 | AK16: 700.4 | AL16: 701.4 | AM16: 702.4 | AN16: 703.4 | AO16: 704.4 | AP16: 705.4 | AQ16: 706.5 | AR16: 707.5 | AS16: 708.5 | AT16: 709.5 | AU16: 710.5 | AV16: 711.5 | AW16: 712.5 | AX16: 713.5 | AY16: 714.5 | AZ16: 715.5 | BA16: 716.5 | BB16: 717.5 | BC16: 718.5 | BD16: 719.5 | BE16: 720.6 | BF16: 721.6 | BG16: 722.6 | BH16: 723.6 | BI16: 724.6 | BJ16: 725.6 | BK16: 726.6 | BL16: 727.6 | BM16: 728.6 | BN16: 729.6 | BO16: 730.6 | BP16: 731.6 | BQ16: 732.6 | BR16: 733.7 | BS16: 734.7 | BT16: 735.7 | BU16: 736.7 | BV16: 737.7 | BW16: 738.7 | BX16: 739.7 | BY16: 740.7 | BZ16: 741.7 | CA16: 742.7 | CB16: 743.7 | CC16: 744.7 | CD16: 745.7 | CE16: 746.7 | CF16: 747.7 | CG16: 748.8 | CH16: 749.8 | CI16: 750.8 | CJ16: 751.8 | CK16: 752.8 | CL16: 753.8 | CM16: 754.8 | CN16: 755.8 | CO16: 756.8 | CP16: 757.8 | CQ16: 758.8 | CR16: 759.8 | CS16: 760.8 | CT16: 761.8 | CU16: 762.8 | CV16: 763.9 | CW16: 764.9 | CX16: 765.9 | CY16: 766.9 | CZ16: 767.9 | DA16: 768.9 | DB16: 769.9 | DC16: =DB16+1 -> 770.9 | DD16: =DC16+1 -> 771.9 | DE16: =DD16+1 -> 772.9 | DF16: =DE16+1 -> 773.9 | DG16: =DF16+1 -> 774.9 | DH16: =DG16+1 -> 775.9 | DI16: =DH16+1 -> 776.9 | DJ16: =DI16+1 -> 777.9 | ... DL16: =DK16+1 -> 779.9 | DM16: 781.8 | DN16: 782.9 | DO16: 784 | DP16: 785.1 | DQ16: 786.2 | DR16: 787.3 | DS16: 788.3 | DT16: 789.3 | DU16: 790.3 | DV16: 791.3 | DW16: 792.3 | DX16: 793.3 | DY16: 794.4 | DZ16: 795.4 | EA16: 796.4 | EB16: 797.4 | EC16: 798.4 | ED16: 799.4 | EE16: 800.4 | EF16: 801.4 | EG16: 802.4 | EH16: 803.4 | EI16: 804.5 | EJ16: 805.5 | EK16: 806.5 | EL16: 807.5 | EM16: 808.5 | EN16: 809.5 | EO16: 810.5 | EP16: 811.5 | EQ16: 812.5 | ER16: 813.5 | ES16: 814.6 | ET16: 815.6 | EU16: 816.6 | EV16: 817.6 | EW16: 818.6 | EX16: 819.6 | EY16: 820.6 | EZ16: 821.6 | FA16: 822.6 | FB16: 823.6 | FC16: 824.7 | FD16: 825.7 | FE16: 826.7 | FF16: 827.7 | FG16: 828.7 | FH16: 829.7 | FI16: 830.7 | FJ16: 831.7 | FK16: 832.7 | FL16: 833.7 | FM16: 834.7 | FN16: 835.8 | FO16: 836.8 | FP16: 837.8 | FQ16: 838.8 | FR16: 839.8 | FS16: 840.8 | FT16: 841.8 | FU16: 842.8 | FV16: 843.8 | FW16: 844.8 | FX16: 845.8 | FY16: 846.8 | FZ16: 847.8 | GA16: 848.8 | GB16: 849.8 | GC16: 850.8 | GD16: 851.8 | GE16: 852.8 | GF16: 853.8 | GG16: 854.8 | GH16: 855.8 | GI16: 856.8 | GJ16: 857.8 | GK16: 858.8 | GL16: 859.8 | GM16: 860.8 | GN16: 861.8 | GO16: 862.8 | GP16: 863.9 | GQ16: 864.9 | GR16: 865.9 | GS16: 866.9 | GT16: 867.9 | GU16: 868.9 | GV16: 869.9 | GW16: 870.9 | GX16: 871.9 | GY16: 872.9 | GZ16: 873.9 | HA16: 874.9 | HB16: 875.9 | HC16: 876.9 | HD16: 877.9 | HE16: 878.9 | HF16: 879.9 | HG16: 880.9 | HH16: 881.9 | HI16: 882.9 | HJ16: 883.9 | HK16: 884.9 | HL16: 885.9 | HM16: 886.9 | HN16: 887.9 | HO16: 888.9 | HP16: 889.9 | HQ16: 890.9 | HR16: 891.9 | HS16: 892.9 | HT16: 893.9 | HU16: 894.9 | HV16: 895.9 | HW16: 896.9 | HX16: 897.9 | HY16: 898.9 | HZ16: 900 | IA16: 901 | IB16: 902 | IC16: 903 | ID16: 904 | IE16: 905 | IF16: 906 | IG16: 907 | IH16: 908 | II16: 909 | IJ16: 910 | IK16: 911 | IL16: 912 | IM16: 913 | IN16: 914 | IO16: 915 | IP16: 916 | IQ16: 917 | IR16: 918 | IS16: 919 | IT16: 920 | IU16: 921 | IV16: 922
A17: 5 | B17: 660.6 | C17: 661.6 | D17: 662.6 | E17: 663.6 | F17: 664.6 | G17: 665.6 | H17: 666.6 | I17: 667.6 | J17: 668.6 | K17: 671.7 | L17: 675.7 | M17: 676.7 | N17: 677.7 | O17: 678.7 | P17: 679.7 | Q17: 680.7 | R17: 681.7 | S17: 682.7 | T17: 683.7 | U17: 684.8 | V17: 685.8 | W17: 686.8 | X17: 687.8 | Y17: 688.8 | Z17: 689.8 | AA17: 690.8 | AB17: 691.8 | AC17: 692.8 | AD17: 693.8 | AE17: 694.8 | AF17: 695.8 | AG17: 696.8 | AH17: 697.8 | AI17: 698.9 | AJ17: 699.9 | AK17: 700.9 | AL17: 701.9 | AM17: 702.9 | AN17: 703.9 | AO17: 704.9 | AP17: 705.9 | AQ17: 706.9 | AR17: 707.9 | AS17: 708.9 | AT17: 709.9 | AU17: 710.9 | AV17: 711.9 | AW17: 713 | AX17: 714 | AY17: 715 | AZ17: 716 | BA17: 717 | BB17: 718 | BC17: 719 | BD17: 720 | BE17: 721 | BF17: 722 | BG17: 723 | BH17: 724 | BI17: 725 | BJ17: 726 | BK17: 727.1 | BL17: 728.1 | BM17: 729.1 | BN17: 730.1 | BO17: 731.1 | BP17: 732.1 | BQ17: 733.1 | BR17: 734.1 | BS17: 735.1 | BT17: 736.1 | BU17: 737.1 | BV17: 738.1 | BW17: 739.1 | BX17: 740.1 | BY17: 741.1 | BZ17: 742.1 | CA17: 743.2 | CB17: 744.2 | CC17: 745.2 | CD17: 746.2 | CE17: 747.2 | CF17: 748.2 | CG17: 749.2 | CH17: 750.2 | CI17: 751.2 | CJ17: 752.2 | CK17: 753.2 | CL17: 754.2 | CM17: 755.2 | CN17: 756.2 | CO17: 757.2 | CP17: 758.2 | CQ17: 759.3 | CR17: 760.3 | CS17: 761.3 | CT17: 762.3 | CU17: 763.3 | CV17: 764.3 | CW17: 765.3 | CX17: 766.3 | CY17: 767.3 | CZ17: 768.3 | DA17: 769.3 | DB17: 770.3 | DC17: =DB17+1 -> 771.3 | DD17: =DC17+1 -> 772.3 | DE17: =DD17+1 -> 773.3 | DF17: =DE17+1 -> 774.3 | DG17: =DF17+1 -> 775.3 | DH17: =DG17+1 -> 776.3 | DI17: =DH17+1 -> 777.3 | DJ17: =DI17+1 -> 778.3 | ... DL17: =DK17+1 -> 780.3 | DM17: 782.2 | DN17: 783.3 | DO17: 784.4 | DP17: 785.5 | DQ17: 786.6 | DR17: 787.7 | DS17: 788.7 | DT17: 789.7 | DU17: 790.7 | DV17: 791.7 | DW17: 792.7 | DX17: 793.7 | DY17: 794.7 | DZ17: 795.7 | EA17: 796.7 | EB17: 797.7 | EC17: 798.8 | ED17: 799.8 | EE17: 800.8 | EF17: 801.8 | EG17: 802.8 | EH17: 803.8 | EI17: 804.8 | EJ17: 805.8 | EK17: 806.8 | EL17: 807.9 | EM17: 808.9 | EN17: 809.9 | EO17: 810.9 | EP17: 811.9 | EQ17: 812.9 | ER17: 813.9 | ES17: 814.9 | ET17: 815.9 | EU17: 816.9 | EV17: 817.9 | EW17: 819 | EX17: 820 | EY17: 821 | EZ17: 822 | FA17: 823 | FB17: 824 | FC17: 825 | FD17: 826 | FE17: 827 | FF17: 828 | FG17: 829 | FH17: 830 | FI17: 831.1 | FJ17: 832.1 | FK17: 833.1 | FL17: 834.1 | FM17: 835.1 | FN17: 836.1 | FO17: 837.1 | FP17: 838.1 | FQ17: 839.1 | FR17: 840.1 | FS17: 841.1 | FT17: 842.1 | FU17: 843.1 | FV17: 844.1 | FW17: 845.1 | FX17: 846.1 | FY17: 847.1 | FZ17: 848.1 | GA17: 849.2 | GB17: 850.2 | GC17: 851.2 | GD17: 852.2 | GE17: 853.2 | GF17: 854.2 | GG17: 855.2 | GH17: 856.2 | GI17: 857.2 | GJ17: 858.2 | GK17: 859.2 | GL17: 860.2 | GM17: 861.2 | GN17: 862.2 | GO17: 863.2 | GP17: 864.2 | GQ17: 865.2 | GR17: 866.2 | GS17: 867.2 | GT17: 868.2 | GU17: 869.2 | GV17: 870.2 | GW17: 871.2 | GX17: 872.2 | GY17: 873.2 | GZ17: 874.2 | HA17: 875.2 | HB17: 876.2 | HC17: 877.2 | HD17: 878.2 | HE17: 879.2 | HF17: 880.2 | HG17: 881.2 | HH17: 882.2 | HI17: 883.2 | HJ17: 884.2 | HK17: 885.2 | HL17: 886.2 | HM17: 887.2 | HN17: 888.3 | HO17: 889.3 | HP17: 890.3 | HQ17: 891.3 | HR17: 892.3 | HS17: 893.3 | HT17: 894.3 | HU17: 895.3 | HV17: 896.3 | HW17: 897.3 | HX17: 898.3 | HY17: 899.3 | HZ17: 900.3 | IA17: 901.3 | IB17: 902.3 | IC17: 903.3 | ID17: 904.3 | IE17: 905.3 | IF17: 906.3 | IG17: 907.3 | IH17: 908.3 | II17: 909.3 | IJ17: 910.3 | IK17: 911.3 | IL17: 912.3 | IM17: 913.3 | IN17: 914.3 | IO17: 915.3 | IP17: 916.3 | IQ17: 917.3 | IR17: 918.3 | IS17: 919.3 | IT17: 920.3 | IU17: 921.3 | IV17: 922.3
A18: 5.5 | B18: 661 | C18: 662 | D18: 663.1 | E18: 664.1 | F18: 665.1 | G18: 666.1 | H18: 667.1 | I18: 668.1 | J18: 669.1 | K18: 672.1 | L18: 676.2 | M18: 677.2 | N18: 678.2 | O18: 679.2 | P18: 680.2 | Q18: 681.2 | R18: 682.2 | S18: 683.2 | T18: 684.2 | U18: 685.2 | V18: 686.2 | W18: 687.2 | X18: 688.2 | Y18: 689.2 | Z18: 690.2 | AA18: 691.3 | AB18: 692.3 | AC18: 693.3 | AD18: 694.3 | AE18: 695.3 | AF18: 696.3 | AG18: 697.3 | AH18: 698.3 | AI18: 699.3 | AJ18: 700.3 | AK18: 701.3 | AL18: 702.3 | AM18: 703.3 | AN18: 704.3 | AO18: 705.4 | AP18: 706.4 | AQ18: 707.4 | AR18: 708.4 | AS18: 709.4 | AT18: 710.4 | AU18: 711.4 | AV18: 712.4 | AW18: 713.4 | AX18: 714.4 | AY18: 715.4 | AZ18: 716.4 | BA18: 717.4 | BB18: 718.4 | BC18: 719.4 | BD18: 720.5 | BE18: 721.5 | BF18: 722.5 | BG18: 723.5 | BH18: 724.5 | BI18: 725.5 | BJ18: 726.5 | BK18: 727.5 | BL18: 728.5 | BM18: 729.5 | BN18: 730.5 | BO18: 731.5 | BP18: 732.5 | BQ18: 733.5 | BR18: 734.5 | BS18: 735.5 | BT18: 736.6 | BU18: 737.6 | BV18: 738.6 | BW18: 739.6 | BX18: 740.6 | BY18: 741.6 | BZ18: 742.6 | CA18: 743.6 | CB18: 744.6 | CC18: 745.6 | CD18: 746.6 | CE18: 747.6 | CF18: 748.6 | CG18: 749.6 | CH18: 750.6 | CI18: 751.6 | CJ18: 752.6 | CK18: 753.7 | CL18: 754.7 | CM18: 755.7 | CN18: 756.7 | CO18: 757.7 | CP18: 758.7 | CQ18: 759.7 | CR18: 760.7 | CS18: 761.7 | CT18: 762.7 | CU18: 763.7 | CV18: 764.7 | CW18: 765.7 | CX18: 766.7 | CY18: 767.7 | CZ18: 768.7 | DA18: 769.8 | DB18: 770.8 | DC18: =DB18+1 -> 771.8 | DD18: =DC18+1 -> 772.8 | DE18: =DD18+1 -> 773.8 | DF18: =DE18+1 -> 774.8 | DG18: =DF18+1 -> 775.8 | DH18: =DG18+1 -> 776.8 | DI18: =DH18+1 -> 777.8 | DJ18: =DI18+1 -> 778.8 | ... DL18: =DK18+1 -> 780.8 | DM18: 782.7 | DN18: 783.7 | DO18: 784.8 | DP18: 785.9 | DQ18: 787 | DR18: 788 | DS18: 789 | DT18: 790 | DU18: 791.1 | DV18: 792.1 | DW18: 793.1 | DX18: 794.1 | DY18: 795.1 | DZ18: 796.1 | EA18: 797.1 | EB18: 798.1 | EC18: 799.1 | ED18: 800.1 | EE18: 801.1 | EF18: 802.2 | EG18: 803.2 | EH18: 804.2 | EI18: 805.2 | EJ18: 806.2 | EK18: 807.2 | EL18: 808.2 | EM18: 809.2 | EN18: 810.2 | EO18: 811.2 | EP18: 812.2 | EQ18: 813.3 | ER18: 814.3 | ES18: 815.3 | ET18: 816.3 | EU18: 817.3 | EV18: 818.3 | EW18: 819.3 | EX18: 820.3 | EY18: 821.3 | EZ18: 822.3 | FA18: 823.3 | FB18: 824.3 | FC18: 825.4 | FD18: 826.4 | FE18: 827.4 | FF18: 828.4 | FG18: 829.4 | FH18: 830.4 | FI18: 831.4 | FJ18: 832.4 | FK18: 833.4 | FL18: 834.4 | FM18: 835.4 | FN18: 836.4 | FO18: 837.5 | FP18: 838.5 | FQ18: 839.5 | FR18: 840.5 | FS18: 841.5 | FT18: 842.5 | FU18: 843.5 | FV18: 844.5 | FW18: 845.5 | FX18: 846.5 | FY18: 847.5 | FZ18: 848.5 | GA18: 849.5 | GB18: 850.5 | GC18: 851.5 | GD18: 852.5 | GE18: 853.5 | GF18: 854.5 | GG18: 855.5 | GH18: 856.5 | GI18: 857.5 | GJ18: 858.5 | GK18: 859.5 | GL18: 860.5 | GM18: 861.5 | GN18: 862.5 | GO18: 863.5 | GP18: 864.5 | GQ18: 865.5 | GR18: 866.5 | GS18: 867.5 | GT18: 868.5 | GU18: 869.5 | GV18: 870.5 | GW18: 871.5 | GX18: 872.6 | GY18: 873.6 | GZ18: 874.6 | HA18: 875.6 | HB18: 876.6 | HC18: 877.6 | HD18: 878.6 | HE18: 879.6 | HF18: 880.6 | HG18: 881.6 | HH18: 882.6 | HI18: 883.6 | HJ18: 884.6 | HK18: 885.6 | HL18: 886.6 | HM18: 887.6 | HN18: 888.6 | HO18: 889.6 | HP18: 890.6 | HQ18: 891.6 | HR18: 892.6 | HS18: 893.6 | HT18: 894.6 | HU18: 895.6 | HV18: 896.6 | HW18: 897.6 | HX18: 898.6 | HY18: 899.6 | HZ18: 900.6 | IA18: 901.6 | IB18: 902.6 | IC18: 903.6 | ID18: 904.6 | IE18: 905.6 | IF18: 906.6 | IG18: 907.6 | IH18: 908.6 | II18: 909.6 | IJ18: 910.6 | IK18: 911.6 | IL18: 912.6 | IM18: 913.7 | IN18: 914.7 | IO18: 915.7 | IP18: 916.7 | IQ18: 917.7 | IR18: 918.7 | IS18: 919.7 | IT18: 920.7 | IU18: 921.7 | IV18: 922.7
... A89: 41 | B89: 694.2 | C89: 695.2 | D89: 696.2 | E89: 697.2 | F89: 698.1 | G89: 699.1 | H89: 700.1 | I89: 701.1 | J89: 702.1 | K89: 705 | L89: 708.9 | M89: 709.9 | N89: 710.9 | O89: 711.9 | P89: 712.8 | Q89: 713.8 | R89: 714.8 | S89: 715.8 | T89: 716.8 | U89: 717.8 | V89: 718.7 | W89: 719.7 | X89: 720.7 | Y89: 721.7 | Z89: 722.7 | AA89: 723.6 | AB89: 724.6 | AC89: 725.6 | AD89: 726.6 | AE89: 727.6 | AF89: 728.6 | AG89: 729.5 | AH89: 730.5 | AI89: 731.5 | AJ89: 732.5 | AK89: 733.5 | AL89: 734.5 | AM89: 735.4 | AN89: 736.4 | AO89: 737.4 | AP89: 738.4 | AQ89: 739.4 | AR89: 740.3 | AS89: 741.3 | AT89: 742.3 | AU89: 743.3 | AV89: 744.3 | AW89: 745.3 | AX89: 746.2 | AY89: 747.2 | AZ89: 748.2 | BA89: 749.2 | BB89: 750.2 | BC89: 751.2 | BD89: 752.1 | BE89: 753.1 | BF89: 754.1 | BG89: 755.1 | BH89: 756.1 | BI89: 757.1 | BJ89: 758 | BK89: 759 | BL89: 760 | BM89: 761 | BN89: 762 | BO89: 763 | BP89: 763.9 | BQ89: 764.9 | BR89: 765.9 | BS89: 766.9 | BT89: 767.9 | BU89: 768.9 | BV89: 769.8 | BW89: 770.8 | BX89: 771.6 | BY89: 772.4 | BZ89: 773.2 | CA89: 774.1 | CB89: 774.9 | CC89: 775.7 | CD89: 776.6 | CE89: 777.4 | CF89: 778.2 | CG89: 779 | CH89: 779.9 | CI89: 780.7 | CJ89: 781.5 | CK89: 782.3 | CL89: 783.2 | CM89: 784 | CN89: 784.8 | CO89: 785.7 | CP89: 786.5 | CQ89: 787.3 | CR89: 788.3 | CS89: 789.3 | CT89: 790.2 | CU89: 791.2 | CV89: 792.2 | CW89: 793.2 | CX89: 794.1 | CY89: 795.1 | CZ89: 796.1 | DA89: 797 | DB89: 798 | DC89: =DB89+1 -> 799 | DD89: =DC89+1 -> 800 | DE89: =DD89+1 -> 801 | DF89: =DE89+1 -> 802 | DG89: =DF89+1 -> 803 | DH89: =DG89+1 -> 804 | DI89: =DH89+1 -> 805 | DJ89: =DI89+1 -> 806 | ... DL89: =DK89+1 -> 808 | DM89: 808.8 | DN89: 809.7 | DO89: 810.7 | DP89: 811.7 | DQ89: 812.7 | DR89: 813.6 | DS89: 814.6 | DT89: 815.6 | DU89: 816.6 | DV89: 817.5 | DW89: 818.5 | DX89: 819.5 | DY89: 820.5 | DZ89: 821.5 | EA89: 822.4 | EB89: 823.4 | EC89: 824.4 | ED89: 825.4 | EE89: 826.3 | EF89: 827.3 | EG89: 828.3 | EH89: 829.3 | EI89: 830.2 | EJ89: 831.2 | EK89: 832.2 | EL89: 833.2 | EM89: 834.1 | EN89: 835.1 | EO89: 836.1 | EP89: 837.1 | EQ89: 838.1 | ER89: 839 | ES89: 840 | ET89: 841 | EU89: 842 | EV89: 843 | EW89: 844 | EX89: 845 | EY89: 846 | EZ89: 847 | FA89: 848 | FB89: 849 | FC89: 850 | FD89: 851 | FE89: 852 | FF89: 852.9 | FG89: 853.9 | FH89: 854.9 | FI89: 855.9 | FJ89: 856.9 | FK89: 857.9 | FL89: 858.9 | FM89: 859.9 | FN89: 860.9 | FO89: 861.9 | FP89: 862.9 | FQ89: 863.9 | FR89: 864.9 | FS89: 865.8 | FT89: 866.8 | FU89: 867.8 | FV89: 868.8 | FW89: 869.8 | FX89: 870.8 | FY89: 871.8 | FZ89: 872.8 | GA89: 873.8 | GB89: 874.8 | GC89: 875.8 | GD89: 876.8 | GE89: 877.8 | GF89: 878.8 | GG89: 879.7 | GH89: 880.7 | GI89: 881.7 | GJ89: 882.7 | GK89: 883.7 | GL89: 884.7 | GM89: 885.7 | GN89: 886.7 | GO89: 887.7 | GP89: 888.7 | GQ89: 889.7 | GR89: 890.7 | GS89: 891.7 | GT89: 892.7 | GU89: 893.6 | GV89: 894.6 | GW89: 895.6 | GX89: 896.6 | GY89: 897.6 | GZ89: 898.6 | HA89: 899.6 | HB89: 900.6 | HC89: 901.6 | HD89: 902.6 | HE89: 903.6 | HF89: 904.6 | HG89: 905.6 | HH89: 906.6 | HI89: 907.6 | HJ89: 908.6 | HK89: 909.5 | HL89: 910.5 | HM89: 911.5 | HN89: 912.5 | HO89: 913.5 | HP89: 914.5 | HQ89: 915.5 | HR89: 916.5 | HS89: 917.5 | HT89: 918.5 | HU89: 919.5 | HV89: 920.5 | HW89: 921.5 | HX89: 922.5 | HY89: 923.5 | HZ89: 924.4 | IA89: 925.4 | IB89: 926.4 | IC89: 927.4 | ID89: 928.4 | IE89: 929.4 | IF89: 930.4 | IG89: 931.4 | IH89: 932.4 | II89: 933.4 | IJ89: 934.4 | IK89: 935.4 | IL89: 936.4 | IM89: 937.4 | IN89: 938.4 | IO89: 939.4 | IP89: 940.3 | IQ89: 941.3 | IR89: 942.3 | IS89: 943.3 | IT89: 944.3 | IU89: 945.3 | IV89: 946.3
A90: 41.5 | B90: 694.7 | C90: 695.6 | D90: 696.6 | E90: 697.6 | F90: 698.6 | G90: 699.6 | H90: 700.6 | I90: 701.5 | J90: 702.5 | K90: 705.5 | L90: 709.4 | M90: 710.4 | N90: 711.3 | O90: 712.3 | P90: 713.3 | Q90: 714.3 | R90: 715.3 | S90: 716.2 | T90: 717.2 | U90: 718.2 | V90: 719.2 | W90: 720.2 | X90: 721.2 | Y90: 722.1 | Z90: 723.1 | AA90: 724.1 | AB90: 725.1 | AC90: 726.1 | AD90: 727 | AE90: 728 | AF90: 729 | AG90: 730 | AH90: 731 | AI90: 732 | AJ90: 732.9 | AK90: 733.9 | AL90: 734.9 | AM90: 735.9 | AN90: 736.9 | AO90: 737.8 | AP90: 738.8 | AQ90: 739.8 | AR90: 740.8 | AS90: 741.8 | AT90: 742.8 | AU90: 743.7 | AV90: 744.7 | AW90: 745.7 | AX90: 746.7 | AY90: 747.7 | AZ90: 748.7 | BA90: 749.6 | BB90: 750.6 | BC90: 751.6 | BD90: 752.6 | BE90: 753.6 | BF90: 754.5 | BG90: 755.5 | BH90: 756.5 | BI90: 757.5 | BJ90: 758.5 | BK90: 759.5 | BL90: 760.4 | BM90: 761.4 | BN90: 762.4 | BO90: 763.4 | BP90: 764.4 | BQ90: 765.4 | BR90: 766.4 | BS90: 767.3 | BT90: 768.3 | BU90: 769.3 | BV90: 770.3 | BW90: 771.1 | BX90: 771.9 | BY90: 772.8 | BZ90: 773.6 | CA90: 774.4 | CB90: 775.2 | CC90: 776.1 | CD90: 776.9 | CE90: 777.7 | CF90: 778.5 | CG90: 779.4 | CH90: 780.2 | CI90: 781 | CJ90: 781.9 | CK90: 782.7 | CL90: 783.5 | CM90: 784.3 | CN90: 785.2 | CO90: 786 | CP90: 786.8 | CQ90: 787.7 | CR90: 788.6 | CS90: 789.6 | CT90: 790.6 | CU90: 791.6 | CV90: 792.5 | CW90: 793.5 | CX90: 794.5 | CY90: 795.5 | CZ90: 796.4 | DA90: 797.4 | DB90: 798.4 | DC90: =DB90+1 -> 799.4 | DD90: =DC90+1 -> 800.4 | DE90: =DD90+1 -> 801.4 | DF90: =DE90+1 -> 802.4 | DG90: =DF90+1 -> 803.4 | DH90: =DG90+1 -> 804.4 | DI90: =DH90+1 -> 805.4 | DJ90: =DI90+1 -> 806.4 | ... DL90: =DK90+1 -> 808.4 | DM90: 809.1 | DN90: 810.1 | DO90: 811.1 | DP90: 812 | DQ90: 813 | DR90: 814 | DS90: 815 | DT90: 815.9 | DU90: 816.9 | DV90: 817.9 | DW90: 818.9 | DX90: 819.8 | DY90: 820.8 | DZ90: 821.8 | EA90: 822.8 | EB90: 823.8 | EC90: 824.7 | ED90: 825.7 | EE90: 826.7 | EF90: 827.7 | EG90: 828.6 | EH90: 829.6 | EI90: 830.6 | EJ90: 831.6 | EK90: 832.5 | EL90: 833.5 | EM90: 834.5 | EN90: 835.5 | EO90: 836.4 | EP90: 837.4 | EQ90: 838.4 | ER90: 839.4 | ES90: 840.4 | ET90: 841.4 | EU90: 842.4 | EV90: 843.4 | EW90: 844.4 | EX90: 845.3 | EY90: 846.3 | EZ90: 847.3 | FA90: 848.3 | FB90: 849.3 | FC90: 850.3 | FD90: 851.3 | FE90: 852.3 | FF90: 853.3 | FG90: 854.3 | FH90: 855.3 | FI90: 856.3 | FJ90: 857.3 | FK90: 858.3 | FL90: 859.2 | FM90: 860.2 | FN90: 861.2 | FO90: 862.2 | FP90: 863.2 | FQ90: 864.2 | FR90: 865.2 | FS90: 866.2 | FT90: 867.2 | FU90: 868.2 | FV90: 869.2 | FW90: 870.2 | FX90: 871.2 | FY90: 872.1 | FZ90: 875.1 | GA90: 876.1 | GB90: 877.1 | GE90: 878.1 | GF90: 879.1 | GG90: 880.1 | GH90: 881.1 | GI90: 882.1 | GJ90: 883.1 | GK90: 884.1 | GL90: 885.1 | GM90: 886 | GN90: 887 | GO90: 888 | GP90: 889 | GQ90: 890 | GR90: 891 | GS90: 892 | GT90: 893 | GU90: 894 | GV90: 895 | GW90: 896 | GX90: 897 | GY90: 898 | GZ90: 899 | HA90: 899.9 | HB90: 900.9 | HC90: 901.9 | HD90: 902.9 | HE90: 903.9 | HF90: 904.9 | HG90: 905.9 | HH90: 906.9 | HI90: 907.9 | HJ90: 908.9 | HK90: 909.9 | HL90: 910.9 | HM90: 911.9 | HN90: 912.9 | HO90: 913.9 | HP90: 914.8 | HQ90: 915.8 | HR90: 916.8 | HS90: 917.8 | HT90: 918.8 | HU90: 919.8 | HV90: 920.8 | HW90: 921.8 | HX90: 922.8 | HY90: 923.8 | HZ90: 924.8 | IA90: 925.8 | IB90: 926.8 | IC90: 927.8 | ID90: 928.8 | IE90: 929.7 | IF90: 930.7 | IG90: 931.7 | IH90: 932.7 | II90: 933.7 | IJ90: 934.7 | IK90: 935.7 | IL90: 936.7 | IM90: 937.7 | IN90: 938.7 | IO90: 939.7 | IP90: 940.7 | IQ90: 941.7 | IR90: 942.7 | IS90: 943.7 | IT90: 944.6 | IU90: 945.6 | IV90: 946.6
